Workbook

Sheet By Category
A1: PUBLIC FEEDBACK & DEFECT STATISTICS - Q3 2026
A2: Jul-Sep 2026
A4: Category | B4: Jul | C4: Aug | D4: Sep | E4: Q3 total
A5: Structural | B5: =COUNTIFS('Feedback Q3'!$F$2:$F$316,$A5,'Feedback Q3'!$B$2:$B$316,">="&DATE(2026,7,1),'Feedback Q3'!$B$2:$B$316,"<"&DATE(2026,8,1)) | C5: =COUNTIFS('Feedback Q3'!$F$2:$F$316,$A5,'Feedback Q3'!$B$2:$B$316,">="&DATE(2026,8,1),'Feedback Q3'!$B$2:$B$316,"<"&DATE(2026,9,1)) | D5: =COUNTIFS('Feedback Q3'!$F$2:$F$316,$A5,'Feedback Q3'!$B$2:$B$316,">="&DATE(2026,9,1),'Feedback Q3'!$B$2:$B$316,"<"&DATE(2026,10,1)) | E5: =SUM(B5:D5)
A6: Water Seepage / Leak | B6: =COUNTIFS('Feedback Q3'!$F$2:$F$316,$A6,'Feedback Q3'!$B$2:$B$316,">="&DATE(2026,7,1),'Feedback Q3'!$B$2:$B$316,"<"&DATE(2026,8,1)) | C6: =COUNTIFS('Feedback Q3'!$F$2:$F$316,$A6,'Feedback Q3'!$B$2:$B$316,">="&DATE(2026,8,1),'Feedback Q3'!$B$2:$B$316,"<"&DATE(2026,9,1)) | D6: =COUNTIFS('Feedback Q3'!$F$2:$F$316,$A6,'Feedback Q3'!$B$2:$B$316,">="&DATE(2026,9,1),'Feedback Q3'!$B$2:$B$316,"<"&DATE(2026,10,1)) | E6: =SUM(B6:D6)
A7: Plumbing & Sanitary | B7: =COUNTIFS('Feedback Q3'!$F$2:$F$316,$A7,'Feedback Q3'!$B$2:$B$316,">="&DATE(2026,7,1),'Feedback Q3'!$B$2:$B$316,"<"&DATE(2026,8,1)) | C7: =COUNTIFS('Feedback Q3'!$F$2:$F$316,$A7,'Feedback Q3'!$B$2:$B$316,">="&DATE(2026,8,1),'Feedback Q3'!$B$2:$B$316,"<"&DATE(2026,9,1)) | D7: =COUNTIFS('Feedback Q3'!$F$2:$F$316,$A7,'Feedback Q3'!$B$2:$B$316,">="&DATE(2026,9,1),'Feedback Q3'!$B$2:$B$316,"<"&DATE(2026,10,1)) | E7: =SUM(B7:D7)
A8: Electrical | B8: =COUNTIFS('Feedback Q3'!$F$2:$F$316,$A8,'Feedback Q3'!$B$2:$B$316,">="&DATE(2026,7,1),'Feedback Q3'!$B$2:$B$316,"<"&DATE(2026,8,1)) | C8: =COUNTIFS('Feedback Q3'!$F$2:$F$316,$A8,'Feedback Q3'!$B$2:$B$316,">="&DATE(2026,8,1),'Feedback Q3'!$B$2:$B$316,"<"&DATE(2026,9,1)) | D8: =COUNTIFS('Feedback Q3'!$F$2:$F$316,$A8,'Feedback Q3'!$B$2:$B$316,">="&DATE(2026,9,1),'Feedback Q3'!$B$2:$B$316,"<"&DATE(2026,10,1)) | E8: =SUM(B8:D8)
A9: Fire Safety | B9: =COUNTIFS('Feedback Q3'!$F$2:$F$316,$A9,'Feedback Q3'!$B$2:$B$316,">="&DATE(2026,7,1),'Feedback Q3'!$B$2:$B$316,"<"&DATE(2026,8,1)) | C9: =COUNTIFS('Feedback Q3'!$F$2:$F$316,$A9,'Feedback Q3'!$B$2:$B$316,">="&DATE(2026,8,1),'Feedback Q3'!$B$2:$B$316,"<"&DATE(2026,9,1)) | D9: =COUNTIFS('Feedback Q3'!$F$2:$F$316,$A9,'Feedback Q3'!$B$2:$B$316,">="&DATE(2026,9,1),'Feedback Q3'!$B$2:$B$316,"<"&DATE(2026,10,1)) | E9: =SUM(B9:D9)
A10: Pest | B10: =COUNTIFS('Feedback Q3'!$F$2:$F$316,$A10,'Feedback Q3'!$B$2:$B$316,">="&DATE(2026,7,1),'Feedback Q3'!$B$2:$B$316,"<"&DATE(2026,8,1)) | C10: =COUNTIFS('Feedback Q3'!$F$2:$F$316,$A10,'Feedback Q3'!$B$2:$B$316,">="&DATE(2026,8,1),'Feedback Q3'!$B$2:$B$316,"<"&DATE(2026,9,1)) | D10: =COUNTIFS('Feedback Q3'!$F$2:$F$316,$A10,'Feedback Q3'!$B$2:$B$316,">="&DATE(2026,9,1),'Feedback Q3'!$B$2:$B$316,"<"&DATE(2026,10,1)) | E10: =SUM(B10:D10)
A11: Hygiene (Tenant) | B11: =COUNTIFS('Feedback Q3'!$F$2:$F$316,$A11,'Feedback Q3'!$B$2:$B$316,">="&DATE(2026,7,1),'Feedback Q3'!$B$2:$B$316,"<"&DATE(2026,8,1)) | C11: =COUNTIFS('Feedback Q3'!$F$2:$F$316,$A11,'Feedback Q3'!$B$2:$B$316,">="&DATE(2026,8,1),'Feedback Q3'!$B$2:$B$316,"<"&DATE(2026,9,1)) | D11: =COUNTIFS('Feedback Q3'!$F$2:$F$316,$A11,'Feedback Q3'!$B$2:$B$316,">="&DATE(2026,9,1),'Feedback Q3'!$B$2:$B$316,"<"&DATE(2026,10,1)) | E11: =SUM(B11:D11)
A12: Obstruction / Encroachment | B12: =COUNTIFS('Feedback Q3'!$F$2:$F$316,$A12,'Feedback Q3'!$B$2:$B$316,">="&DATE(2026,7,1),'Feedback Q3'!$B$2:$B$316,"<"&DATE(2026,8,1)) | C12: =COUNTIFS('Feedback Q3'!$F$2:$F$316,$A12,'Feedback Q3'!$B$2:$B$316,">="&DATE(2026,8,1),'Feedback Q3'!$B$2:$B$316,"<"&DATE(2026,9,1)) | D12: =COUNTIFS('Feedback Q3'!$F$2:$F$316,$A12,'Feedback Q3'!$B$2:$B$316,">="&DATE(2026,9,1),'Feedback Q3'!$B$2:$B$316,"<"&DATE(2026,10,1)) | E12: =SUM(B12:D12)
A13: Noise / Nuisance | B13: =COUNTIFS('Feedback Q3'!$F$2:$F$316,$A13,'Feedback Q3'!$B$2:$B$316,">="&DATE(2026,7,1),'Feedback Q3'!$B$2:$B$316,"<"&DATE(2026,8,1)) | C13: =COUNTIFS('Feedback Q3'!$F$2:$F$316,$A13,'Feedback Q3'!$B$2:$B$316,">="&DATE(2026,8,1),'Feedback Q3'!$B$2:$B$316,"<"&DATE(2026,9,1)) | D13: =COUNTIFS('Feedback Q3'!$F$2:$F$316,$A13,'Feedback Q3'!$B$2:$B$316,">="&DATE(2026,9,1),'Feedback Q3'!$B$2:$B$316,"<"&DATE(2026,10,1)) | E13: =SUM(B13:D13)
A14: Common Area (Town Council) | B14: =COUNTIFS('Feedback Q3'!$F$2:$F$316,$A14,'Feedback Q3'!$B$2:$B$316,">="&DATE(2026,7,1),'Feedback Q3'!$B$2:$B$316,"<"&DATE(2026,8,1)) | C14: =COUNTIFS('Feedback Q3'!$F$2:$F$316,$A14,'Feedback Q3'!$B$2:$B$316,">="&DATE(2026,8,1),'Feedback Q3'!$B$2:$B$316,"<"&DATE(2026,9,1)) | D14: =COUNTIFS('Feedback Q3'!$F$2:$F$316,$A14,'Feedback Q3'!$B$2:$B$316,">="&DATE(2026,9,1),'Feedback Q3'!$B$2:$B$316,"<"&DATE(2026,10,1)) | E14: =SUM(B14:D14)
A15: General Enquiry / Non-defect | B15: =COUNTIFS('Feedback Q3'!$F$2:$F$316,$A15,'Feedback Q3'!$B$2:$B$316,">="&DATE(2026,7,1),'Feedback Q3'!$B$2:$B$316,"<"&DATE(2026,8,1)) | C15: =COUNTIFS('Feedback Q3'!$F$2:$F$316,$A15,'Feedback Q3'!$B$2:$B$316,">="&DATE(2026,8,1),'Feedback Q3'!$B$2:$B$316,"<"&DATE(2026,9,1)) | D15: =COUNTIFS('Feedback Q3'!$F$2:$F$316,$A15,'Feedback Q3'!$B$2:$B$316,">="&DATE(2026,9,1),'Feedback Q3'!$B$2:$B$316,"<"&DATE(2026,10,1)) | E15: =SUM(B15:D15)
A16: Total | B16: =SUM(B5:B15) | C16: =SUM(C5:C15) | D16: =SUM(D5:D15) | E16: =SUM(E5:E15)
A17: (Static count: 315 cases received in Q3)

Sheet Feedback Q3
A1: Feedback ID | B1: Received | C1: Channel | D1: Unit | E1: Category code | F1: Category | G1: Severity | H1: Team | I1: i-EMS ticket | J1: Status | K1: Description
A2: FB-2026-00573 | B2: 46204 | C2: Walk-in | D2: U-CD108-01-07 | E2: PLB | F2: Plumbing & Sanitary | G2: Medium | H2: M&E | I2: IEMS-2607-0006 | J2: Closed | K2: Floor trap at teh back of Suria Bookstore Pte Ltd choked, dirty water overflowing to common corridor Blk 108.
A3: FB-2026-00574 | B3: 46204 | C3: CityFix App | D3: U-BV266-01-04 | E3: PLB | F3: Plumbing & Sanitary | G3: Medium | H3: M&E | I3: IEMS-2607-0007 | J3: Closed | K3: Floor trap at the back of Ever Joy Education Hub choked, dirty water overflowing to common corridor Blk 266.
A4: FB-2026-00575 | B4: 46204 | C4: CityFix App | D4: U-RH491-01-01 | E4: PLB | F4: Plumbing & Sanitary | G4: Medium | H4: M&E | I4: IEMS-2607-0008 | J4: Closed | K4: Burst pipe near #01-01 Rimba Walk, water gushing out. Please send plumber asap.
A5: FB-2026-00576 | B5: 46204 | C5: Email | D5: U-RH484-01-05 | E5: CMN | F5: Common Area (Town Council) | G5: Low | H5: Town Council Liaison | J5: Closed | K5: Litter and stains along the 5-foot way at Rimba Walk Blk 484.
A6: FB-2026-00577 | B6: 46204 | C6: Walk-in | D6: U-CD181-01-07 | E6: HYG | F6: Hygiene (Tenant) | G6: Low | H6: Estate Compliance | J6: Closed | K6: New Life Hair Studio leaves rubbish bags outside the shop overnight, smelly and attracts flies. Blk 181.
A7: FB-2026-00578 | B7: 46204 | C7: CityFix App | D7: U-CD108-01-07 | E7: NOI | F7: Noise / Nuisance | G7: Low | H7: Estate Compliance | J7: Closed | K7: Delivery lorry unloading at 5am for Suria Bookstore Pte Ltd, very noisy.
A8: FB-2026-00579 | B8: 46205 | C8: Walk-in | D8: U-BV214-01-23 | E8: HYG | F8: Hygiene (Tenant) | G8: Medium | H8: Estate Compliance | J8: Closed | K8: SHOPFRONT OF #01-23 BLK 214 VERY DIRTY, OIL STAINS ON THE FLOOR.
A9: FB-2026-00580 | B9: 46205 | C9: MP Letter | D9: U-CD118-01-26 | E9: PLB | F9: Plumbing & Sanitary | G9: Medium | H9: M&E | I9: IEMS-2607-0009 | J9: Closed | K9: Burst pipe near #01-26 Cendana Road, water gushing out. Please send plumber asap.
A10: FB-2026-00581 | B10: 46205 | C10: Walk-in | D10: U-CD143-01-01 | E10: HYG | F10: Hygiene (Tenant) | G10: Low | H10: Estate Compliance | J10: Closed | K10: Shopfront of #01-01 Blk 143 very dirty, oil stains on teh floor.
A11: FB-2026-00582 | B11: 46206 | C11: Email | D11: U-CD189-01-04 | E11: PST | F11: Pest | G11: Low | H11: Pest Control | I11: IEMS-2607-0010 | J11: Closed | K11: Many rats running around the bin area behind Brilliant Eye Centre Pte Ltd, Blk 189.
A12: FB-2026-00583 | B12: 46206 | C12: CityFix App | D12: U-RH401-01-03 | E12: PST | F12: Pest | G12: Medium | H12: Pest Control | I12: IEMS-2607-0011 | J12: Closed | K12: Many rats running around the bin area behind Ananda Florist, Blk 401.
A13: FB-2026-00584 | B13: 46206 | C13: CityFix App | D13: U-BV290-01-11 | E13: HYG | F13: Hygiene (Tenant) | G13: Low | H13: Estate Compliance | J13: Closed | K13: STRONG GREASE SMELL FROM BAYU STORE PTE LTD KITCHEN EXHAUST, RESIDENTS ABOVE COMPLAINING.
A14: FB-2026-00585 | B14: 46206 | C14: Email | D14: U-ST589-01-02 | E14: CMN | F14: Common Area (Town Council) | G14: Low | H14: Town Council Liaison | J14: Closed | K14: LIFT LOBBY LIGHTS NEAR THE SHOPS AT BLK 589 FAULTY.
A15: FB-2026-00586 | B15: 46206 | C15: Walk-in | D15: U-CD185-01-07 | E15: ELE | F15: Electrical | G15: Medium | H15: M&E | I15: IEMS-2607-0012 | J15: Closed | K15: Power keeps tripping for the row of shops at Blk 185 incl Tian Fu Clinic & Surgery. Fridges affected, food spoiling.
A16: FB-2026-00587 | B16: 46206 | C16: CityFix App | D16: U-KR305-02-19 | E16: HYG | F16: Hygiene (Tenant) | G16: Low | H16: Estate Compliance | J16: Closed | K16: Strong grease smell from Pinnacle Clinic & Surgery kitchen exhaust, residents above complaining.
A17: FB-2026-00588 | B17: 46207 | C17: MP Letter | D17: U-CD118-01-26 | E17: PST | F17: Pest | G17: Medium | H17: Pest Control | I17: IEMS-2607-0013 | J17: Closed | K17: Something wrong with Lotus Family Clinic Pte Ltd at Blk 118, water and smell all over the back lane. Please look into it.
A18: FB-2026-00589 | B18: 46207 | C18: CityFix App | D18: U-ST507-02-04 | E18: PST | F18: Pest | G18: Medium | H18: Pest Control | I18: IEMS-2607-0014 | J18: Closed | K18: Termites found eating the door frame of Evergreen Tuition Centre Pte Ltd (#02-04).
A19: FB-2026-00590 | B19: 46207 | C19: CityFix App | D19: U-PI627-01-33 | E19: NOI | F19: Noise / Nuisance | G19: High | H19: Estate Compliance | J19: Closed | K19: Cosy Minimart Pte Ltd at Blk 627 operating till 2am with loud music. Residents cannot sleep.
A20: FB-2026-00591 | B20: 46207 | C20: MP Letter | D20: U-ST545-01-07 | E20: PLB | F20: Plumbing & Sanitary | G20: Medium | H20: M&E | I20: IEMS-2607-0015 | J20: Closed | K20: Toilet at rear of Blk 545 shops (near #01-07) cannot flush, pipe leaking.
A21: FB-2026-00592 | B21: 46207 | C21: Hotline | D21: U-KR368-01-09 | E21: PLB | F21: Plumbing & Sanitary | G21: Medium | H21: M&E | J21: Closed | K21: Something wrong with Pinnacle Provision Shop at Blk 368, water and smell all over the back lane. Please look into it.
A22: FB-2026-00593 | B22: 46208 | C22: Walk-in | D22: U-PI614-01-05 | E22: SEP | F22: Water Seepage / Leak | G22: Medium | H22: Civil & Structural | I22: IEMS-2607-0016 | J22: Closed | K22: Water seepage from the wall between #01-05 and next unit at Blk 614. Wall paint peeling, smells musty.
A23: FB-2026-00594 | B23: 46208 | C23: MP Letter | D23: U-BV204-01-07 | E23: STR | F23: Structural | G23: High | H23: Civil & Structural | I23: IEMS-2607-0017 | J23: Closed | K23: THERE IS A LONG CRACK ON THE COLUMN BESIDE #01-07 BLK 204. GETTING BIGGER OVER THE PAST MONTH. PLEASE CHECK IF STRUCTURE IS SAFE.
A24: FB-2026-00595 | B24: 46208 | C24: CityFix App | D24: U-CD105-01-03 | E24: PLB | F24: Plumbing & Sanitary | G24: Medium | H24: M&E | J24: Closed | K24: Something wrong with Hock Lee Laundry at Blk 105, water and smell all over the back lane. Please look into it.
A25: FB-2026-00596 | B25: 46209 | C25: CityFix App | D25: U-CD142-01-05 | E25: NOI | F25: Noise / Nuisance | G25: Low | H25: Estate Compliance | J25: Closed | K25: Karaoke noise from #01-05 Cendana Street 11 every night.
A26: FB-2026-00597 | B26: 46209 | C26: Hotline | D26: U-PI609-01-03 | E26: HYG | F26: Hygiene (Tenant) | G26: Low | H26: Estate Compliance | J26: Closed | K26: Shopfront of #01-03 Blk 609 very dirty, oil stains on the floor.
A27: FB-2026-00598 | B27: 46209 | C27: CityFix App | D27: U-KR318-02-10 | E27: PST | F27: Pest | G27: Medium | H27: Pest Control | J27: Closed | K27: Lim's Clinic & Surgery Pte Ltd renovation very noisy and dust everywhere, also something cracked on the wall??
A28: FB-2026-00599 | B28: 46209 | C28: Walk-in | D28: U-KR330-01-07 | E28: SEP | F28: Water Seepage / Leak | G28: Medium | H28: Civil & Structural | I28: IEMS-2607-0018 | J28: Closed | K28: Roof slab above Blk 330 #01-07 leaking into shop. Have reported twice before!!
A29: FB-2026-00600 | B29: 46209 | C29: Hotline | D29: U-KR335-01-10 | E29: STR | F29: Structural | G29: High | H29: Civil & Structural | I29: IEMS-2607-0019 | J29: Closed | K29: There is a long crack on the column beside #01-10 Blk 335. Getting bigger over the past month. Please check if structure is safe.
A30: FB-2026-00601 | B30: 46210 | C30: Hotline | D30: U-PI634-01-08 | E30: HYG | F30: Hygiene (Tenant) | G30: Low | H30: Estate Compliance | J30: Closed | K30: Prima Flowers & Gifts leaves rubbish bags outside the shop overnight, smelly and attracts flies. Blk 634.
A31: FB-2026-00602 | B31: 46210 | C31: Hotline | D31: U-KR345-01-11 | E31: SEP | F31: Water Seepage / Leak | G31: Medium | H31: Civil & Structural | J31: Closed | K31: Ceiling near Lakshmi Trading Pte Ltd wet and lights flickering, scared got short circuit.
A32: FB-2026-00603 | B32: 46211 | C32: Hotline | D32: U-RH471-01-01 | E32: ELE | F32: Electrical | G32: High | H32: M&E | I32: IEMS-2607-0020 | J32: Closed | K32: Corridor lights in front of Kumar Eye Centre Pte Ltd not working for a week, very dark at night, unsafe.
A33: FB-2026-00604 | B33: 46211 | C33: MP Letter | D33: U-CD152-01-10 | E33: ELE | F33: Electrical | G33: Low | H33: M&E | I33: IEMS-2607-0021 | J33: Closed | K33: Power keeps tripping for the row of shops at Blk 152 incl Ong & Sons Aquarium & Pets Pte Ltd. Fridges affected, food spoiling.
A34: FB-2026-00605 | B34: 46211 | C34: Walk-in | D34: U-PI627-01-10 | E34: PLB | F34: Plumbing & Sanitary | G34: Low | H34: M&E | I34: IEMS-2607-0022 | J34: Closed | K34: BURST PIPE NEAR #01-10 PASIR INDAH STREET 62, WATER GUSHING OUT. PLEASE SEND PLUMBER ASAP.
A35: FB-2026-00606 | B35: 46211 | C35: MP Letter | D35: U-PI657-02-01 | E35: ENC | F35: Obstruction / Encroachment | G35: Low | H35: Estate Compliance | J35: Closed | K35: Racks of Old Town Consultancy (#02-01) placed beyond the yellow line, blocking pedestrians.
A36: FB-2026-00607 | B36: 46212 | C36: CityFix App | D36: U-RH466-01-07 | E36: ENC | F36: Obstruction / Encroachment | G36: Low | H36: Estate Compliance | J36: Closed | K36: Racks of Smart Kids Bakery (#01-07) placed beyond the yellow line, blocking pedestrians.
A37: FB-2026-00608 | B37: 46213 | C37: CityFix App | D37: U-ST513-01-08 | E37: ENC | F37: Obstruction / Encroachment | G37: Low | H37: Estate Compliance | J37: Closed | K37: Racks of Kian Huat Medical Hall Pte Ltd (#01-08) placed beyond the yellow line, blocking pedestrians.
A38: FB-2026-00609 | B38: 46214 | C38: CityFix App | D38: U-RH466-01-03 | E38: HYG | F38: Hygiene (Tenant) | G38: Low | H38: Estate Compliance | J38: Closed | K38: Hock Lee Fruits Pte Ltd leaves rubbish bags outside the shop overnight, smelly and attracts flies. Blk 466.
A39: FB-2026-00610 | B39: 46214 | C39: Hotline | D39: U-KR330-01-01 | E39: PST | F39: Pest | G39: Medium | H39: Pest Control | I39: IEMS-2607-0023 | J39: Closed | K39: Many rats running around the bin area behind Rainbow Remittance Pte Ltd, Blk 330.
A40: FB-2026-00611 | B40: 46214 | C40: Hotline | D40: U-BV214-01-25 | E40: NOI | F40: Noise / Nuisance | G40: Low | H40: Estate Compliance | J40: Closed | K40: Delivery lorry unloading at 5am for Thye Hin Florist Pte Ltd, very noisy.
...

Sheet i-EMS SLA
A1: Team | B1: Tickets raised | C1: Closed | D1: SLA met | E1: SLA % | F1: Misrouted
A2: Civil & Structural | B2: 61 | C2: 54 | D2: 40 | E2: =IF(C2=0,"",D2/C2) | F2: 3
A3: Estate Compliance | B3: 8 | C3: 7 | D3: 7 | E3: =IF(C3=0,"",D3/C3) | F3: 0
A4: M&E | B4: 63 | C4: 57 | D4: 34 | E4: =IF(C4=0,"",D4/C4) | F4: 2
A5: Pest Control | B5: 32 | C5: 25 | D5: 19 | E5: =IF(C5=0,"",D5/C5) | F5: 0
