Workbook

Sheet Summary
A1: INSPECTION TRACKER 2026
A2: Counts by month and outcome (formulas on Tracker sheet)
A4: Month | B4: Compliant | C4: Minor Breach | D4: Major Breach | E4: Total
A5: 46023 | B5: =COUNTIFS(Tracker!$B$2:$B$1866,">="&$A5,Tracker!$B$2:$B$1866,"<"&EDATE($A5,1),Tracker!$H$2:$H$1866,"Compliant") | C5: =COUNTIFS(Tracker!$B$2:$B$1866,">="&$A5,Tracker!$B$2:$B$1866,"<"&EDATE($A5,1),Tracker!$H$2:$H$1866,"Minor Breach") | D5: =COUNTIFS(Tracker!$B$2:$B$1866,">="&$A5,Tracker!$B$2:$B$1866,"<"&EDATE($A5,1),Tracker!$H$2:$H$1866,"Major Breach") | E5: =SUM(B5:D5)
A6: 46054 | B6: =COUNTIFS(Tracker!$B$2:$B$1866,">="&$A6,Tracker!$B$2:$B$1866,"<"&EDATE($A6,1),Tracker!$H$2:$H$1866,"Compliant") | C6: =COUNTIFS(Tracker!$B$2:$B$1866,">="&$A6,Tracker!$B$2:$B$1866,"<"&EDATE($A6,1),Tracker!$H$2:$H$1866,"Minor Breach") | D6: =COUNTIFS(Tracker!$B$2:$B$1866,">="&$A6,Tracker!$B$2:$B$1866,"<"&EDATE($A6,1),Tracker!$H$2:$H$1866,"Major Breach") | E6: =SUM(B6:D6)
A7: 46082 | B7: =COUNTIFS(Tracker!$B$2:$B$1866,">="&$A7,Tracker!$B$2:$B$1866,"<"&EDATE($A7,1),Tracker!$H$2:$H$1866,"Compliant") | C7: =COUNTIFS(Tracker!$B$2:$B$1866,">="&$A7,Tracker!$B$2:$B$1866,"<"&EDATE($A7,1),Tracker!$H$2:$H$1866,"Minor Breach") | D7: =COUNTIFS(Tracker!$B$2:$B$1866,">="&$A7,Tracker!$B$2:$B$1866,"<"&EDATE($A7,1),Tracker!$H$2:$H$1866,"Major Breach") | E7: =SUM(B7:D7)
A8: 46113 | B8: =COUNTIFS(Tracker!$B$2:$B$1866,">="&$A8,Tracker!$B$2:$B$1866,"<"&EDATE($A8,1),Tracker!$H$2:$H$1866,"Compliant") | C8: =COUNTIFS(Tracker!$B$2:$B$1866,">="&$A8,Tracker!$B$2:$B$1866,"<"&EDATE($A8,1),Tracker!$H$2:$H$1866,"Minor Breach") | D8: =COUNTIFS(Tracker!$B$2:$B$1866,">="&$A8,Tracker!$B$2:$B$1866,"<"&EDATE($A8,1),Tracker!$H$2:$H$1866,"Major Breach") | E8: =SUM(B8:D8)
A9: 46143 | B9: =COUNTIFS(Tracker!$B$2:$B$1866,">="&$A9,Tracker!$B$2:$B$1866,"<"&EDATE($A9,1),Tracker!$H$2:$H$1866,"Compliant") | C9: =COUNTIFS(Tracker!$B$2:$B$1866,">="&$A9,Tracker!$B$2:$B$1866,"<"&EDATE($A9,1),Tracker!$H$2:$H$1866,"Minor Breach") | D9: =COUNTIFS(Tracker!$B$2:$B$1866,">="&$A9,Tracker!$B$2:$B$1866,"<"&EDATE($A9,1),Tracker!$H$2:$H$1866,"Major Breach") | E9: =SUM(B9:D9)
A10: 46174 | B10: =COUNTIFS(Tracker!$B$2:$B$1866,">="&$A10,Tracker!$B$2:$B$1866,"<"&EDATE($A10,1),Tracker!$H$2:$H$1866,"Compliant") | C10: =COUNTIFS(Tracker!$B$2:$B$1866,">="&$A10,Tracker!$B$2:$B$1866,"<"&EDATE($A10,1),Tracker!$H$2:$H$1866,"Minor Breach") | D10: =COUNTIFS(Tracker!$B$2:$B$1866,">="&$A10,Tracker!$B$2:$B$1866,"<"&EDATE($A10,1),Tracker!$H$2:$H$1866,"Major Breach") | E10: =SUM(B10:D10)
A11: 46204 | B11: =COUNTIFS(Tracker!$B$2:$B$1866,">="&$A11,Tracker!$B$2:$B$1866,"<"&EDATE($A11,1),Tracker!$H$2:$H$1866,"Compliant") | C11: =COUNTIFS(Tracker!$B$2:$B$1866,">="&$A11,Tracker!$B$2:$B$1866,"<"&EDATE($A11,1),Tracker!$H$2:$H$1866,"Minor Breach") | D11: =COUNTIFS(Tracker!$B$2:$B$1866,">="&$A11,Tracker!$B$2:$B$1866,"<"&EDATE($A11,1),Tracker!$H$2:$H$1866,"Major Breach") | E11: =SUM(B11:D11)
A12: 46235 | B12: =COUNTIFS(Tracker!$B$2:$B$1866,">="&$A12,Tracker!$B$2:$B$1866,"<"&EDATE($A12,1),Tracker!$H$2:$H$1866,"Compliant") | C12: =COUNTIFS(Tracker!$B$2:$B$1866,">="&$A12,Tracker!$B$2:$B$1866,"<"&EDATE($A12,1),Tracker!$H$2:$H$1866,"Minor Breach") | D12: =COUNTIFS(Tracker!$B$2:$B$1866,">="&$A12,Tracker!$B$2:$B$1866,"<"&EDATE($A12,1),Tracker!$H$2:$H$1866,"Major Breach") | E12: =SUM(B12:D12)
A13: 46266 | B13: =COUNTIFS(Tracker!$B$2:$B$1866,">="&$A13,Tracker!$B$2:$B$1866,"<"&EDATE($A13,1),Tracker!$H$2:$H$1866,"Compliant") | C13: =COUNTIFS(Tracker!$B$2:$B$1866,">="&$A13,Tracker!$B$2:$B$1866,"<"&EDATE($A13,1),Tracker!$H$2:$H$1866,"Minor Breach") | D13: =COUNTIFS(Tracker!$B$2:$B$1866,">="&$A13,Tracker!$B$2:$B$1866,"<"&EDATE($A13,1),Tracker!$H$2:$H$1866,"Major Breach") | E13: =SUM(B13:D13)
A15: NB officer names typed inconsistently - use Officer ID mapping in PLG Records for reporting.

Sheet Tracker
A1: Inspection ID | B1: Date | C1: Unit | D1: Town | E1: Officer | F1: Type | G1: Finding | H1: Outcome | I1: F/U due | J1: Closed | K1: Days to close | L1: Status
A2: INSP-2026-0001 | B2: 46023 | C2: U-BV219-01-09 | D2: Bayshore Vale | E2: D. Ong | F2: Routine | G2: NONE | H2: Compliant | K2: =IF(J2="","",J2-B2) | L2: =IF(H2="Compliant","N/A",IF(J2<>"","Closed",IF(I2<DATE(2026,9,30),"OVERDUE","Open")))
A3: INSP-2026-0002 | B3: 46023 | C3: U-RH455-01-21 | D3: Rimba Heights | E3: Ben Ho | F3: Routine | G3: DISPLAY_ENCROACH | H3: Minor Breach | I3: 46037 | J3: 46042 | K3: =IF(J3="","",J3-B3) | L3: =IF(H3="Compliant","N/A",IF(J3<>"","Closed",IF(I3<DATE(2026,9,30),"OVERDUE","Open")))
A4: INSP-2026-0003 | B4: 46023 | C4: U-BV229-01-09 | D4: Bayshore Vale | E4: Daniel O. | F4: Routine | G4: UNAUTH_TRADE | H4: Major Breach | I4: 46030 | J4: 46030 | K4: =IF(J4="","",J4-B4) | L4: =IF(H4="Compliant","N/A",IF(J4<>"","Closed",IF(I4<DATE(2026,9,30),"OVERDUE","Open")))
A5: INSP-2026-0004 | B5: 46024 | C5: U-ST528-01-13 | D5: Sungai Tinggi | E5: Ben Ho | F5: Routine | G5: NONE | H5: Compliant | K5: =IF(J5="","",J5-B5) | L5: =IF(H5="Compliant","N/A",IF(J5<>"","Closed",IF(I5<DATE(2026,9,30),"OVERDUE","Open")))
A6: INSP-2026-0005 | B6: 46024 | C6: U-KR333-01-01 | D6: Kebun Raya | E6: D. Ong | F6: Routine | G6: DISPLAY_ENCROACH | H6: Minor Breach | I6: 46038 | J6: 46037 | K6: =IF(J6="","",J6-B6) | L6: =IF(H6="Compliant","N/A",IF(J6<>"","Closed",IF(I6<DATE(2026,9,30),"OVERDUE","Open")))
A7: INSP-2026-0006 | B7: 46024 | C7: U-KR345-01-03 | D7: Kebun Raya | E7: B. Ho | F7: Complaint-driven | G7: NONE | H7: Compliant | K7: =IF(J7="","",J7-B7) | L7: =IF(H7="Compliant","N/A",IF(J7<>"","Closed",IF(I7<DATE(2026,9,30),"OVERDUE","Open")))
A8: INSP-2026-0007 | B8: 46024 | C8: U-ST579-01-02 | D8: Sungai Tinggi | E8: Daniel Ong | F8: Routine | G8: NONE | H8: Compliant | K8: =IF(J8="","",J8-B8) | L8: =IF(H8="Compliant","N/A",IF(J8<>"","Closed",IF(I8<DATE(2026,9,30),"OVERDUE","Open")))
A9: INSP-2026-0008 | B9: 46024 | C9: U-RH401-01-05 | D9: Rimba Heights | E9: D. Ong | F9: Routine | G9: NONE | H9: Compliant | K9: =IF(J9="","",J9-B9) | L9: =IF(H9="Compliant","N/A",IF(J9<>"","Closed",IF(I9<DATE(2026,9,30),"OVERDUE","Open")))
A10: INSP-2026-0009 | B10: 46024 | C10: U-BV297-02-06 | D10: Bayshore Vale | E10: M. Lim | F10: Routine | G10: HYGIENE | H10: Minor Breach | I10: 46038 | J10: 46047 | K10: =IF(J10="","",J10-B10) | L10: =IF(H10="Compliant","N/A",IF(J10<>"","Closed",IF(I10<DATE(2026,9,30),"OVERDUE","Open")))
A11: INSP-2026-0010 | B11: 46024 | C11: U-RH482-01-01 | D11: Rimba Heights | E11: Benjamin Ho | F11: Routine | G11: NONE | H11: Compliant | K11: =IF(J11="","",J11-B11) | L11: =IF(H11="Compliant","N/A",IF(J11<>"","Closed",IF(I11<DATE(2026,9,30),"OVERDUE","Open")))
A12: INSP-2026-0011 | B12: 46024 | C12: U-PI609-01-02 | D12: Pasir Indah | E12: Marcus Lim | F12: Follow-up | G12: NONE | H12: Compliant | K12: =IF(J12="","",J12-B12) | L12: =IF(H12="Compliant","N/A",IF(J12<>"","Closed",IF(I12<DATE(2026,9,30),"OVERDUE","Open")))
A13: INSP-2026-0012 | B13: 46025 | C13: U-RH428-01-04 | D13: Rimba Heights | E13: daniel ong | F13: Routine | G13: NONE | H13: Compliant | K13: =IF(J13="","",J13-B13) | L13: =IF(H13="Compliant","N/A",IF(J13<>"","Closed",IF(I13<DATE(2026,9,30),"OVERDUE","Open")))
A14: INSP-2026-0013 | B14: 46026 | C14: U-CD109-01-10 | D14: Cendana | E14: Daniel O. | F14: Follow-up | G14: NONE | H14: Compliant | K14: =IF(J14="","",J14-B14) | L14: =IF(H14="Compliant","N/A",IF(J14<>"","Closed",IF(I14<DATE(2026,9,30),"OVERDUE","Open")))
A15: INSP-2026-0014 | B15: 46026 | C15: U-CD136-01-06 | D15: Cendana | E15: Marcus Lim | F15: Routine | G15: NONE | H15: Compliant | K15: =IF(J15="","",J15-B15) | L15: =IF(H15="Compliant","N/A",IF(J15<>"","Closed",IF(I15<DATE(2026,9,30),"OVERDUE","Open")))
A16: INSP-2026-0015 | B16: 46026 | C16: U-BV290-01-06 | D16: Bayshore Vale | E16: M. Lim | F16: Routine | G16: NONE | H16: Compliant | K16: =IF(J16="","",J16-B16) | L16: =IF(H16="Compliant","N/A",IF(J16<>"","Closed",IF(I16<DATE(2026,9,30),"OVERDUE","Open")))
A17: INSP-2026-0016 | B17: 46026 | C17: U-KR310-01-07 | D17: Kebun Raya | E17: Daniel O. | F17: Routine | G17: NONE | H17: Compliant | K17: =IF(J17="","",J17-B17) | L17: =IF(H17="Compliant","N/A",IF(J17<>"","Closed",IF(I17<DATE(2026,9,30),"OVERDUE","Open")))
A18: INSP-2026-0017 | B18: 46026 | C18: U-PI625-01-05 | D18: Pasir Indah | E18: Daniel Ong | F18: Routine | G18: NONE | H18: Compliant | K18: =IF(J18="","",J18-B18) | L18: =IF(H18="Compliant","N/A",IF(J18<>"","Closed",IF(I18<DATE(2026,9,30),"OVERDUE","Open")))
A19: INSP-2026-0018 | B19: 46026 | C19: U-RH460-01-02 | D19: Rimba Heights | E19: daniel ong | F19: Complaint-driven | G19: NONE | H19: Compliant | K19: =IF(J19="","",J19-B19) | L19: =IF(H19="Compliant","N/A",IF(J19<>"","Closed",IF(I19<DATE(2026,9,30),"OVERDUE","Open")))
A20: INSP-2026-0019 | B20: 46026 | C20: U-RH460-01-05 | D20: Rimba Heights | E20: B. Ho | F20: Routine | G20: NONE | H20: Compliant | K20: =IF(J20="","",J20-B20) | L20: =IF(H20="Compliant","N/A",IF(J20<>"","Closed",IF(I20<DATE(2026,9,30),"OVERDUE","Open")))
A21: INSP-2026-0020 | B21: 46026 | C21: U-PI615-01-13 | D21: Pasir Indah | E21: daniel ong | F21: Routine | G21: NONE | H21: Compliant | K21: =IF(J21="","",J21-B21) | L21: =IF(H21="Compliant","N/A",IF(J21<>"","Closed",IF(I21<DATE(2026,9,30),"OVERDUE","Open")))
A22: INSP-2026-0021 | B22: 46027 | C22: U-BV256-01-11 | D22: Bayshore Vale | E22: marcus | F22: Routine | G22: NONE | H22: Compliant | K22: =IF(J22="","",J22-B22) | L22: =IF(H22="Compliant","N/A",IF(J22<>"","Closed",IF(I22<DATE(2026,9,30),"OVERDUE","Open")))
A23: INSP-2026-0022 | B23: 46027 | C23: U-PI668-01-11 | D23: Pasir Indah | E23: Marcus Lim | F23: Follow-up | G23: NONE | H23: Compliant | K23: =IF(J23="","",J23-B23) | L23: =IF(H23="Compliant","N/A",IF(J23<>"","Closed",IF(I23<DATE(2026,9,30),"OVERDUE","Open")))
A24: INSP-2026-0023 | B24: 46027 | C24: U-RH485-01-02 | D24: Rimba Heights | E24: Ben Ho | F24: Follow-up | G24: DISPLAY_ENCROACH | H24: Minor Breach | I24: 46041 | J24: 46043 | K24: =IF(J24="","",J24-B24) | L24: =IF(H24="Compliant","N/A",IF(J24<>"","Closed",IF(I24<DATE(2026,9,30),"OVERDUE","Open")))
A25: INSP-2026-0024 | B25: 46027 | C25: U-ST564-01-13 | D25: Sungai Tinggi | E25: B. Ho | F25: Follow-up | G25: NONE | H25: Compliant | K25: =IF(J25="","",J25-B25) | L25: =IF(H25="Compliant","N/A",IF(J25<>"","Closed",IF(I25<DATE(2026,9,30),"OVERDUE","Open")))
A26: INSP-2026-0025 | B26: 46027 | C26: U-RH401-01-06 | D26: Rimba Heights | E26: Daniel Ong | F26: Routine | G26: NONE | H26: Compliant | K26: =IF(J26="","",J26-B26) | L26: =IF(H26="Compliant","N/A",IF(J26<>"","Closed",IF(I26<DATE(2026,9,30),"OVERDUE","Open")))
A27: INSP-2026-0026 | B27: 46027 | C27: U-CD142-01-08 | D27: Cendana | E27: Marcus Lim | F27: Routine | G27: NONE | H27: Compliant | K27: =IF(J27="","",J27-B27) | L27: =IF(H27="Compliant","N/A",IF(J27<>"","Closed",IF(I27<DATE(2026,9,30),"OVERDUE","Open")))
A28: INSP-2026-0027 | B28: 46027 | C28: U-RH401-02-04 | D28: Rimba Heights | E28: B. Ho | F28: Routine | G28: NONE | H28: Compliant | K28: =IF(J28="","",J28-B28) | L28: =IF(H28="Compliant","N/A",IF(J28<>"","Closed",IF(I28<DATE(2026,9,30),"OVERDUE","Open")))
A29: INSP-2026-0028 | B29: 46028 | C29: U-BV205-01-11 | D29: Bayshore Vale | E29: M. Lim | F29: Routine | G29: NONE | H29: Compliant | K29: =IF(J29="","",J29-B29) | L29: =IF(H29="Compliant","N/A",IF(J29<>"","Closed",IF(I29<DATE(2026,9,30),"OVERDUE","Open")))
A30: INSP-2026-0029 | B30: 46028 | C30: U-CD120-01-02 | D30: Cendana | E30: daniel ong | F30: Routine | G30: UNAPPROVED_AA | H30: Minor Breach | I30: 46042 | J30: 46043 | K30: =IF(J30="","",J30-B30) | L30: =IF(H30="Compliant","N/A",IF(J30<>"","Closed",IF(I30<DATE(2026,9,30),"OVERDUE","Open")))
A31: INSP-2026-0030 | B31: 46028 | C31: U-PI646-01-05 | D31: Pasir Indah | E31: daniel ong | F31: Follow-up | G31: NONE | H31: Compliant | K31: =IF(J31="","",J31-B31) | L31: =IF(H31="Compliant","N/A",IF(J31<>"","Closed",IF(I31<DATE(2026,9,30),"OVERDUE","Open")))
A32: INSP-2026-0031 | B32: 46028 | C32: U-KR333-01-12 | D32: Kebun Raya | E32: D. Ong | F32: Complaint-driven | G32: NONE | H32: Compliant | K32: =IF(J32="","",J32-B32) | L32: =IF(H32="Compliant","N/A",IF(J32<>"","Closed",IF(I32<DATE(2026,9,30),"OVERDUE","Open")))
A33: INSP-2026-0032 | B33: 46028 | C33: U-ST513-01-09 | D33: Sungai Tinggi | E33: D. Ong | F33: Routine | G33: NONE | H33: Compliant | K33: =IF(J33="","",J33-B33) | L33: =IF(H33="Compliant","N/A",IF(J33<>"","Closed",IF(I33<DATE(2026,9,30),"OVERDUE","Open")))
A34: INSP-2026-0033 | B34: 46028 | C34: U-RH455-01-10 | D34: Rimba Heights | E34: Daniel O. | F34: Routine | G34: UNAUTH_TRADE | H34: Major Breach | I34: 46035 | J34: 46032 | K34: =IF(J34="","",J34-B34) | L34: =IF(H34="Compliant","N/A",IF(J34<>"","Closed",IF(I34<DATE(2026,9,30),"OVERDUE","Open")))
A35: INSP-2026-0034 | B35: 46028 | C35: U-PI646-01-03 | D35: Pasir Indah | E35: D. Ong | F35: Routine | G35: NONE | H35: Compliant | K35: =IF(J35="","",J35-B35) | L35: =IF(H35="Compliant","N/A",IF(J35<>"","Closed",IF(I35<DATE(2026,9,30),"OVERDUE","Open")))
A36: INSP-2026-0035 | B36: 46028 | C36: U-ST522-01-04 | D36: Sungai Tinggi | E36: daniel ong | F36: Routine | G36: DISPLAY_ENCROACH | H36: Minor Breach | I36: 46042 | K36: =IF(J36="","",J36-B36) | L36: =IF(H36="Compliant","N/A",IF(J36<>"","Closed",IF(I36<DATE(2026,9,30),"OVERDUE","Open")))
A37: INSP-2026-0036 | B37: 46029 | C37: U-RH482-01-04 | D37: Rimba Heights | E37: Daniel Ong | F37: Routine | G37: NONE | H37: Compliant | K37: =IF(J37="","",J37-B37) | L37: =IF(H37="Compliant","N/A",IF(J37<>"","Closed",IF(I37<DATE(2026,9,30),"OVERDUE","Open")))
A38: INSP-2026-0037 | B38: 46029 | C38: U-ST512-01-05 | D38: Sungai Tinggi | E38: Benjamin Ho | F38: Routine | G38: NONE | H38: Compliant | K38: =IF(J38="","",J38-B38) | L38: =IF(H38="Compliant","N/A",IF(J38<>"","Closed",IF(I38<DATE(2026,9,30),"OVERDUE","Open")))
A39: INSP-2026-0038 | B39: 46029 | C39: U-ST556-02-04 | D39: Sungai Tinggi | E39: Daniel Ong | F39: Follow-up | G39: NONE | H39: Compliant | K39: =IF(J39="","",J39-B39) | L39: =IF(H39="Compliant","N/A",IF(J39<>"","Closed",IF(I39<DATE(2026,9,30),"OVERDUE","Open")))
A40: INSP-2026-0039 | B40: 46029 | C40: U-PI693-01-11 | D40: Pasir Indah | E40: marcus | F40: Follow-up | G40: NONE | H40: Compliant | K40: =IF(J40="","",J40-B40) | L40: =IF(H40="Compliant","N/A",IF(J40<>"","Closed",IF(I40<DATE(2026,9,30),"OVERDUE","Open")))
...
